Workbook

Sheet Summery
B1: Badalgama Work Shop (As At 02/06/2026)
B3: S/No | C3: Item | D3: Qty
B4: 1 | C4: 15W40 (CI-04) Valvoline | D4: ='15W40(CI-04)Valvoline'!$G$277 -> 205.25
B5: 2 | C5: 15W40 (CI-04) Servo | D5: ='15W40(servo)'!$G$74 -> 88
B6: 3 | C6: 15W40 (CI-04) Delogold | D6: ='15W40(Delogold)'!$G$26 -> 0
B7: 4 | C7: DS-10 | D7: ='DS-10 Oil'!$G$31 -> 145
B8: 5 | C8: 20W 50 Oil | D8: ='20W-50'!$G$32 -> 56.5 | M8: ='SERVO-68 HY-OIL'!$G$18 -> 0
B9: 6 | C9: SAE-30 | D9: ='SAE-30'!$G$35 -> 43
B10: 7 | C10: HD-68 Hy/Oil Caltex | D10: ='HD-68 Hy-Oil Caltex'!$G$312 -> 123.25
B11: 8 | C11: SERVO-68 Hy/Oil | D11: ='SERVO-68 HY-OIL'!$G$18 -> 0
B12: 9 | C12: HD-46 Hy/Oil Caltex | D12: ='HD-46 Hy-Oil-Caltex'!$G$36 -> 89
B13: 10 | C13: HD-46 Hy/Oil Servo | D13: ='HD-46 Hy Oil SERVO'!$G$21 -> 0
B14: 11 | C14: Power Oil-1888 | D14: ='Power Oil-1888'!$G$110 -> 94
B15: 12 | C15: MP-90 Gear Oil | D15: ='MP-90 Gear Oil'!$G$137 -> 71.5
B16: 13 | C16: 80W 90 Gear Oil Caltex | D16: ='80W90 (Caltex)'!$G$115 -> 34
B17: 14 | C17: 80W 90 Gear Oil Servo | D17: ='80W90 G-Oil (Servo)'!$G$62 -> 63.5
B18: 15 | C18: MP-140 Gear Oil | D18: ='MP-140 G-Oil'!$G$62 -> 124
B19: 16 | C19: Grease | D19: =Grease!$G$201 -> 203.25
B20: 17 | C20: Karosine Oil | D20: ='K-Oil'!$G$324 -> 3
B21: 18 | C21: Pertrol | D21: =PETROL!$G$39 -> 1.15
B22: 19 | C22: Hub Grease | D22: ='HUB GREASE'!$G$20 -> 4.5
C27: Bandula Ekanayake
C28: Store Keeper

Sheet 15W40(CI-04)Valvoline
A1: Edward & Christie(Pvt)Ltd
A2: Central Work Shop Badalgama
A3: Fuel & Lubricant Stock Book
A4: 15W40 (CI-04)Engine Oil
A6: Date | B6: MR | C6: MTN | D6: Description | E6: Received | F6: Issued | G6: Balance | H6: Remark
A7: 45981 | D7: b/f | G7: 28
A8: 45983 | D8: HEX-37 | F8: 1 | G8: =G7+E8-F8 -> 27
A9: 45983 | D9: VR-40 | F9: 2 | G9: =G8+E9-F9 -> 25
A10: 45984 | B10: 127651 | C10: 64972 | D10: Marawila I Road Project | F10: 20 | G10: =G9+E10-F10 -> 5
A11: 45984 | D11: Excess Received | E11: 11 | G11: =G10+E11-F11 -> 16
A12: 45984 | D12: LO-4824 | F12: 16 | G12: =G11+E12-F12 -> 0
A13: 46000 | B13: 141251 | D13: Main Stores | E13: 200 | G13: =G12+E13-F13 -> 200
A14: 46000 | D14: LK-5041 | F14: 5 | G14: =G13+E14-F14 -> 195
A15: 46000 | D15: SR-05 | F15: 15 | G15: =G14+E15-F15 -> 180
A16: 46001 | D16: LO-4925 | F16: 2 | G16: =G15+E16-F16 -> 178
A17: 46001 | D17: ZA-8337 | F17: 13 | G17: =G16+E17-F17 -> 165
A18: 46001 | D18: 48-4849 | F18: 15 | G18: =G17+E18-F18 -> 150
A19: 46001 | D19: RC-9894 | F19: 6 | G19: =G18+E19-F19 -> 144
A20: 45940 | D20: CM-33 | F20: 1 | G20: =G19+E20-F20 -> 143
A21: 46001 | C21: 71969 | D21: Ruwanwella Water Project | F21: 5 | G21: =G20+E21-F21 -> 138
A22: 46002 | D22: LN-8279 | F22: 40 | G22: =G21+E22-F22 -> 98
A23: 46003 | D23: Electric Compressor | F23: 2 | G23: =G22+E23-F23 -> 96
A24: 46003 | B24: 126910 | D24: Iginimitiya | F24: 10 | G24: =G23+E24-F24 -> 86
A25: 46003 | D25: PR-1469 | F25: 3 | G25: =G24+E25-F25 -> 83
A26: 46004 | D26: PTR-10 | F26: 14 | G26: =G25+E26-F26 -> 69
A27: 46004 | B27: 2224 | C27: 64983 | D27: CEP-03 | F27: 50 | G27: =G26+E27-F27 -> 19
A28: 46005 | D28: PA-4193 | F28: 0.5 | G28: =G27+E28-F28 -> 18.5
A29: 46007 | D29: ZA-7925 | F29: 15 | G29: =G28+E29-F29 -> 3.5
A30: 46007 | B30: 141259 | D30: Main Stores | E30: 200 | G30: =G29+E30-F30 -> 203.5
A31: 46008 | D31: Pile Driver | F31: 7 | G31: =G30+E31-F31 -> 196.5
A32: 46008 | D32: LO-5984 | F32: 15 | G32: =G31+E32-F32 -> 181.5
A33: 46008 | B33: 203560 | C33: 71979 | D33: Batticoloa-LOT/02 | F33: 20 | G33: =G32+E33-F33 -> 161.5
A34: 46008 | B34: 141264 | D34: Main Stores | E34: 200 | G34: =G33+E34-F34 -> 361.5
A35: 46008 | D35: Service Truck | F35: 200 | G35: =G34+E35-F35 -> 161.5
A36: 46009 | D36: DAH-2491 | F36: 1 | G36: =G35+E36-F36 -> 160.5
A37: 46009 | D37: Service Carture Engine | F37: 3 | G37: =G36+E37-F37 -> 157.5
A38: 46009 | D38: 325-3448 | F38: 5 | G38: =G37+E38-F38 -> 152.5
A39: 46009 | D39: LI-3851 | F39: 15 | G39: =G38+E39-F39 -> 137.5
A40: 46009 | B40: 2223 | C40: 71982 | D40: CEP-03-E | F40: 50 | G40: =G39+E40-F40 -> 87.5
A41: 46010 | D41: GL-0019 | F41: 2 | G41: =G40+E41-F41 -> 85.5
...

Sheet 15W40(servo)
A1: Edward & Christie(Pvt)Ltd
A2: Central Work Shop Badalgama
A3: Fuel & Lubricant Stock Book
A4: 15W40 (servo)Engine Oil
A6: Date | B6: MR | C6: MTN | D6: Description | E6: Received | F6: Issued | G6: Balance | H6: Remark
A7: 45822 | D7: From Main Stores | E7: 210 | G7: =E7 -> 210 | H7: Servo
A8: 45822 | D8: PTR-10 | F8: 15 | G8: =G7+E8-F8 -> 195
A9: 45822 | D9: LM-6653 | F9: 1 | G9: =G8+E9-F9 -> 194
A10: 45822 | D10: SR-04 | F10: 10 | G10: =G9+E10-F10 -> 184
A11: 45827 | D11: ZA-0447 | F11: 4 | G11: =G10+E11-F11 -> 180
A12: 45828 | D12: LJ-5203 | F12: 16 | G12: =G11+E12-F12 -> 164
A13: 45829 | D13: ASP-03 | F13: 1.5 | G13: =G12+E13-F13 -> 162.5
A14: 45832 | D14: RF-0748 | F14: 6.5 | G14: =G13+E14-F14 -> 156
A15: 45839 | D15: HS-1794 | F15: 18 | G15: =G14+E15-F15 -> 138
A16: 45846 | D16: 325-5720 | F16: 10 | G16: =G15+E16-F16 -> 128
A17: 45850 | D17: PR-1469 | F17: 1 | G17: =G16+E17-F17 -> 127
A18: 45863 | D18: LD-06 | F18: 1 | G18: =G17+E18-F18 -> 126
A19: 45867 | D19: 48-4849 | F19: 1 | G19: =G18+E19-F19 -> 125
... A26: 45888 | D26: 01Bags Co.Mixer | F26: 3 | G26: =G25+E26-F26 -> 113
A27: 45900 | B27: 206113 | C27: 66449 | D27: Ruwanwella Water Project | F27: 10 | G27: =G26+E27-F27 -> 103
A28: 45904 | D28: Service Bay-Carture | F28: 1 | G28: =G27+E28-F28 -> 102
A29: 45910 | D29: LI-7620 | F29: 16 | G29: =G28+E29-F29 -> 86
A30: 45921 | D30: LO-0434 | F30: 2 | G30: =G29+E30-F30 -> 84
A31: 45936 | D31: AC-38 | F31: 7 | G31: =G30+E31-F31 -> 77
A32: 45938 | D32: FL-02 | F32: 2 | G32: =G31+E32-F32 -> 75
A33: 45941 | D33: 48-4849 | F33: 1 | G33: =G32+E33-F33 -> 74
A34: 45941 | D34: Service Bay-Carture | F34: 1 | G34: =G33+E34-F34 -> 73
A35: 45952 | D35: PR-1469 | F35: 3 | G35: =G34+E35-F35 -> 70
A36: 45967 | D36: DAH-2491 | F36: 6 | G36: =G35+E36-F36 -> 64
A37: 45969 | D37: PR-1469 | F37: 1 | G37: =G36+E37-F37 -> 63
A38: 45970 | B38: 142785 | C38: 64958 | D38: Marawila I Road Project | F38: 20 | G38: =G37+E38-F38 -> 43
A39: 45970 | D39: HU-5097 | F39: 6 | G39: =G38+E39-F39 -> 37
A40: 45971 | D40: LK-5041 | F40: 17 | G40: =G39+E40-F40 -> 20
A41: 45981 | D41: Service Bay-Carture | F41: 1 | G41: =G40+E41-F41 -> 19
A42: 46020 | B42: 141296 | D42: From Main Stores | E42: 210 | G42: =G41+E42-F42 -> 229
A43: 46021 | D43: LK-4061 | F43: 15 | G43: =G42+E43-F43 -> 214
A44: 46021 | D44: PH-3945 | F44: 1 | G44: =G43+E44-F44 -> 213
A45: 46024 | D45: LM-5721 | F45: 16 | G45: =G44+E45-F45 -> 197
A46: 46032 | D46: LD-05 | F46: 26 | G46: =G45+E46-F46 -> 171
A47: 46032 | D47: File hammer | F47: 13 | G47: =G46+E47-F47 -> 158
...

Sheet 15W40(Delogold)
A1: Edward & Christie(Pvt)Ltd
A2: Central Work Shop Badalgama
A3: Fuel & Lubricant Stock Book
A4: 15W40 (Delogold)Engine Oil
A6: Date | B6: MR | C6: MTN | D6: Description | E6: Received | F6: Issued | G6: Balance | H6: Remark
A7: 45809 | D7: B/F | G7: 0
G8: =G7+E8-F8 -> 0
G9: =G8+E9-F9 -> 0
G10: =G9+E10-F10 -> 0
G11: =G10+E11-F11 -> 0
G12: =G11+E12-F12 -> 0
G13: =G12+E13-F13 -> 0
G14: =G13+E14-F14 -> 0
G15: =G14+E15-F15 -> 0
G16: =G15+E16-F16 -> 0
G17: =G16+E17-F17 -> 0
G18: =G17+E18-F18 -> 0
G19: =G18+E19-F19 -> 0
... G26: =G25+E26-F26 -> 0

Sheet DS-10 Oil
A1: Edward & Christie(Pvt)Ltd
A2: Central Work Shop Badalgama
A3: Fuel & Lubricant Stock Book
A4: DS-10 Engine Oil
A6: Date | B6: MR | C6: MTN | D6: Description | E6: Received | F6: Issued | G6: Balance | H6: Remark
A7: 45809 | D7: B/F | G7: 159
A8: 45834 | D8: LD-06 | F8: 1 | G8: =G7+E8-F8 -> 158
A9: 45863 | D9: LD-06 | F9: 2 | G9: =G8+E9-F9 -> 156
A10: 45883 | B10: 76258 | C10: 66407 | D10: Muthur Plant | F10: 10 | G10: =G9+E10-F10 -> 146
A11: 45969 | D11: LD-05 | F11: 0.25 | G11: =G10+E11-F11 -> 145.75
A12: 46009 | D12: LD-06 | F12: 0.5 | G12: =G11+E12-F12 -> 145.25
A13: 46022 | D13: LD-05 | F13: 0.25 | G13: =G12+E13-F13 -> 145
G14: =G13+E14-F14 -> 145
G15: =G14+E15-F15 -> 145
G16: =G15+E16-F16 -> 145
G17: =G16+E17-F17 -> 145
G18: =G17+E18-F18 -> 145
G19: =G18+E19-F19 -> 145
G20: =G19+E20-F20 -> 145
G21: =G20+E21-F21 -> 145
G22: =G21+E22-F22 -> 145
G23: =G22+E23-F23 -> 145
G24: =G23+E24-F24 -> 145
G25: =G24+E25-F25 -> 145
... G31: =G30+E31-F31 -> 145

Sheet 20W-50
A1: Edward & Christie(Pvt)Ltd
A2: Central Work Shop Badalgama
A3: Fuel & Lubricant Stock Book
A4: 20W-50 Engine Oil
A6: Date | B6: MR | C6: MTN | D6: Description | E6: Received | F6: Issued | G6: Balance | H6: Remark
A7: 45809 | D7: B/F Balance | G7: 154
A8: 45809 | D8: PR-1504 | F8: 0.5 | G8: =G7+E8-F8 -> 153.5
A9: 45815 | D9: PR-1504 | F9: 0.5 | G9: =G8+E9-F9 -> 153
A10: 45883 | D10: Muthur Plant | F10: 53 | G10: =G9+E10-F10 -> 100
A11: 45962 | B11: 81404 | C11: 71347 | D11: Muthur Plant | F11: 30 | G11: =G10+E11-F11 -> 70
A12: 46028 | D12: PA-4879 | F12: 6.5 | G12: =G11+E12-F12 -> 63.5
A13: 46060 | D13: PH-6742 | F13: 7 | G13: =G12+E13-F13 -> 56.5
G14: =G13+E14-F14 -> 56.5
G15: =G14+E15-F15 -> 56.5
G16: =G15+E16-F16 -> 56.5
G17: =G16+E17-F17 -> 56.5
G18: =G17+E18-F18 -> 56.5
G19: =G18+E19-F19 -> 56.5
G20: =G19+E20-F20 -> 56.5
G21: =G20+E21-F21 -> 56.5
G22: =G21+E22-F22 -> 56.5
G23: =G22+E23-F23 -> 56.5
G24: =G23+E24-F24 -> 56.5
G25: =G24+E25-F25 -> 56.5
... G32: =G31+E32-F32 -> 56.5

Sheet SAE-30
A1: Edward & Christie(Pvt)Ltd
A2: Central Work Shop Badalgama
A3: Fuel & Lubricant Stock Book
A4: SAE-30 Engine Oil
A6: Date | B6: MR | C6: MTN | D6: Description | E6: Received | F6: Issued | G6: Balance | H6: Remark
A7: 45809 | D7: B/F Balance | G7: 185
A8: 45828 | D8: Service team | F8: 20 | G8: =G7+E8-F8 -> 165
A9: 45860 | D9: LD-05 | F9: 22 | G9: =G8+E9-F9 -> 143
A10: 45867 | D10: Excess Received | E10: 12 | G10: =G9+E10-F10 -> 155
A11: 45867 | D11: Service team | F11: 155 | G11: =G10+E11-F11 -> 0
A12: 45867 | D12: Returned From Service | E12: 5 | G12: =G11+E12-F12 -> 5
A13: 45984 | D13: LD-05 | F13: 1 | G13: =G12+E13-F13 -> 4
A14: 46009 | D14: LD-06 | F14: 4 | G14: =G13+E14-F14 -> 0
A15: 46066 | B15: 142497 | D15: From Main Stores | E15: 210 | G15: =G14+E15-F15 -> 210
A16: 46066 | D16: LD-08 | F16: 20 | G16: =G15+E16-F16 -> 190
A17: 46069 | D17: LD-08 | F17: 20 | G17: =G16+E17-F17 -> 170
A18: 46082 | D18: MG-03 | F18: 3 | G18: =G17+E18-F18 -> 167
A19: 46084 | D19: Service team | F19: 50 | G19: =G18+E19-F19 -> 117 | H19: LD-09
A20: 46096 | D20: LD-08 | F20: 30 | G20: =G19+E20-F20 -> 87
A21: 46153 | D21: ZB-2587 Bob Cat JCB Service | F21: 44 | G21: =G20+E21-F21 -> 43
G22: =G21+E22-F22 -> 43
G23: =G22+E23-F23 -> 43
G24: =G23+E24-F24 -> 43
G25: =G24+E25-F25 -> 43
G26: =G25+E26-F26 -> 43
G27: =G26+E27-F27 -> 43
G28: =G27+E28-F28 -> 43
G29: =G28+E29-F29 -> 43
G30: =G29+E30-F30 -> 43
G31: =G30+E31-F31 -> 43
G32: =G31+E32-F32 -> 43
G33: =G32+E33-F33 -> 43
... G35: =G34+E35-F35 -> 43

Sheet HD-68 Hy-Oil Caltex
A1: Edward & Christie(Pvt)Ltd
A2: Central Work Shop Badalgama
A3: Fuel & Lubricant Stock Book
A4: HD-68 Hy/Oil
A6: Date | B6: MR | C6: MTN | D6: Description | E6: Received | F6: Issued | G6: Balance | H6: Remark
A7: 45809 | D7: B/F- Balance | G7: 102.5
A8: 45809 | D8: FL-02 | F8: 15 | G8: =G7+E8-F8 -> 87.5
A9: 45810 | D9: Service Team | F9: 87.5 | G9: =G8+E9-F9 -> 0
A10: 45811 | D10: From Main Stores | E10: 210 | G10: =G9+E10-F10 -> 210
A11: 45811 | B11: 1812 | C11: 2456 | D11: CEP-03 | F11: 100 | G11: =G10+E11-F11 -> 110
A12: 45813 | D12: C.Com | F12: 50 | G12: =G11+E12-F12 -> 60
A13: 45814 | B13: 4768 | C13: 2460 | D13: TM-20-Kilinochchi | F13: 10 | G13: =G12+E13-F13 -> 50
A14: 45817 | D14: Returned From C.Com | E14: 50 | G14: =G13+E14-F14 -> 100
A15: 45820 | D15: LI-3402 | F15: 5 | G15: =G14+E15-F15 -> 95
A16: 45821 | B16: 23932 | C16: 2468 | D16: Ruwanwella W/P | F16: 30 | G16: =G15+E16-F16 -> 65
A17: 45822 | D17: From Main Stores | E17: 210 | G17: =G16+E17-F17 -> 275
A18: 45822 | B18: 203319 | C18: 2469 | D18: Batticoloa-LOT-03 | F18: 70 | G18: =G17+E18-F18 -> 205
A19: 45824 | D19: Rtd From Service Team | E19: 10 | G19: =G18+E19-F19 -> 215
A20: 45824 | B20: 21019 | C20: 2471 | D20: ZA-0447 JCB (Iginimitiya) | F20: 10 | G20: =G19+E20-F20 -> 205
A21: 45825 | B21: 112799 | C21: 2474 | D21: Batticoloa-LOT-02 | F21: 70 | G21: =G20+E21-F21 -> 135
A22: 45827 | B22: 2394 | C22: 2478 | D22: Ruwanwella W/P | F22: 20 | G22: =G21+E22-F22 -> 115
A23: 45827 | D23: ZA-0447 JCB (Iginimitiya) | F23: 10 | G23: =G22+E23-F23 -> 105
A24: 45828 | D24: Service Team | F24: 15 | G24: =G23+E24-F24 -> 90
A25: 45828 | D25: MG-05 | F25: 10 | G25: =G24+E25-F25 -> 80
A26: 45829 | B26: 180211 | C26: 2484 | D26: Ambanpola W/Project | F26: 15 | G26: =G25+E26-F26 -> 65
A27: 45830 | B27: 7313 | D27: From Main Stores | E27: 210 | G27: =G26+E27-F27 -> 275
A28: 45830 | D28: LB-01/ZA-2609 | F28: 20 | G28: =G27+E28-F28 -> 255
A29: 45831 | D29: MG-05 | F29: 5 | G29: =G28+E29-F29 -> 250
A30: 45833 | D30: HS-1794 | F30: 10 | G30: =G29+E30-F30 -> 240
A31: 45834 | D31: ZA-0447 JCB (Iginimitiya) | F31: 30 | G31: =G30+E31-F31 -> 210
A32: 45835 | D32: HEX-18 | F32: 15 | G32: =G31+E32-F32 -> 195
A33: 45835 | B33: 4774 | C33: 2493 | D33: Kilinochchi. | F33: 30 | G33: =G32+E33-F33 -> 165
A34: 45836 | B34: 113602 | C34: 2495 | D34: Batticoloa-LOT-03 | F34: 50 | G34: =G33+E34-F34 -> 115
A35: 45836 | D35: ZA-2608 | F35: 10 | G35: =G34+E35-F35 -> 105
A36: 45838 | B36: 1876 | C36: 31854 | D36: CEP-03 | F36: 100 | G36: =G35+E36-F36 -> 5
A37: 45840 | B37: 7332 | D37: From Main Stores | E37: 210 | G37: =G36+E37-F37 -> 215
A38: 45840 | D38: MG-05 | F38: 3 | G38: =G37+E38-F38 -> 212
A39: 45841 | D39: LK-4057 | F39: 7 | G39: =G38+E39-F39 -> 205
A40: 45842 | D40: ZA-0447 JCB (Iginimitiya) | F40: 1 | G40: =G39+E40-F40 -> 204
A41: 45842 | D41: VR-44 | F41: 45 | G41: =G40+E41-F41 -> 159
...

Sheet SERVO-68 HY-OIL
A2: Edward & Christie(Pvt)Ltd
A3: Central Work Shop Badalgama
A4: Fuel & Lubricant Stock Book
A5: SERVO-68 Hy/Oil
A7: Date | B7: MR | C7: MTN | D7: Description | E7: Received | F7: Issued | G7: Balance | H7: Remark
A8: 45916 | B8: 7347 | D8: Main Stores | E8: 210 | G8: =E8 -> 210
A9: 45916 | D9: ZA-9716-CR/02 | F9: 70 | G9: =G8+E9-F9 -> 140
A10: 45918 | D10: LK-5047 | F10: 17 | G10: =G9+E10-F10 -> 123
A11: 45959 | D11: LN-8277 | F11: 40 | G11: =G10+E11-F11 -> 83
A12: 45967 | B12: 207020 | C12: 64955 | D12: Bridge No.01& 02-Karathiu | F12: 20 | G12: =G11+E12-F12 -> 63
A13: 45969 | D13: LD-05 | F13: 2 | G13: =G12+E13-F13 -> 61
A14: 45970 | B14: 142785 | C14: 64958 | D14: Marawila Water Project | F14: 20 | G14: =G13+E14-F14 -> 41
A15: 45972 | D15: HEX-29 | F15: 20 | G15: =G14+E15-F15 -> 21
A16: 46008 | D16: LD-05 | F16: 10 | G16: =G15+E16-F16 -> 11
A17: 46011 | D17: HEX-22 | F17: 10 | G17: =G16+E17-F17 -> 1
A18: 46017 | D18: Asphalt Plant | F18: 1 | G18: =G17+E18-F18 -> 0
G19: =G18+E19-F19 -> 0
G20: =G19+E20-F20 -> 0
G21: =G20+E21-F21 -> 0
G22: =G21+E22-F22 -> 0
G23: =G22+E23-F23 -> 0
G24: =G23+E24-F24 -> 0
G25: =G24+E25-F25 -> 0
G26: =G25+E26-F26 -> 0
G27: =G26+E27-F27 -> 0
G28: =G27+E28-F28 -> 0
G29: =G28+E29-F29 -> 0
G30: =G29+E30-F30 -> 0

Sheet HD-46 Hy-Oil-Caltex
A1: Edward & Christie(Pvt)Ltd
A2: Central Work Shop Badalgama
A3: Fuel & Lubricant Stock Book
A4: HD-46 Hy/Oil
A6: Date | B6: MR | C6: MTN | D6: Description | E6: Received | F6: Issued | G6: Balance | H6: Remark
A7: 45854 | B7: 7347 | D7: Main Stores | E7: 210 | G7: =E7 -> 210
A8: 45854 | D8: TM-13 | F8: 10 | G8: =G7+E8-F8 -> 200
A9: 45882 | D9: SL-15 | F9: 15 | G9: =G8+E9-F9 -> 185
A10: 45883 | B10: 172701 | C10: 66408 | D10: Batticoloa-LOT/03 | F10: 20 | G10: =G9+E10-F10 -> 165
A11: 45892 | D11: ZB-2587 | F11: 75 | G11: =G10+E11-F11 -> 90
A12: 45905 | B12: 206119 | C12: 66451 | D12: Ruwanwella | F12: 30 | G12: =G11+E12-F12 -> 60
A13: 45925 | B13: 206954 | C13: 72102 | D13: Batticoloa-LOT/02 | F13: 30 | G13: =G12+E13-F13 -> 30
A14: 45971 | D14: SL-09 | F14: 2 | G14: =G13+E14-F14 -> 28
A15: 45986 | D15: Asphalt Plant | F15: 1 | G15: =G14+E15-F15 -> 27
A16: 46008 | D16: Excess Received | E16: 23 | G16: =G15+E16-F16 -> 50
A17: 46008 | B17: 203560 | C17: 71979 | D17: ICDP-LOT/02 | F17: 50 | G17: =G16+E17-F17 -> 0
A18: 46033 | B18: 142459 | D18: Main Stores | E18: 210 | G18: =G17+E18-F18 -> 210
A19: 46033 | B19: 64998 | C19: 205986 | D19: Ruwanwella | F19: 30 | G19: =G18+E19-F19 -> 180
A20: 46036 | B20: 142464 | D20: Main Stores | E20: 420 | G20: =G19+E20-F20 -> 600
A21: 46036 | B21: 2419 | C21: 58064 | D21: cep/03 CR-02 | F21: 400 | G21: =G20+E21-F21 -> 200
A22: 46073 | B22: 2682 | C22: 58086 | D22: Ruwanwella | F22: 30 | G22: =G21+E22-F22 -> 170
A23: 46093 | D23: SL-06 | F23: 1.5 | G23: =G22+E23-F23 -> 168.5
A24: 46105 | D24: SL-15 | F24: 33.5 | G24: =G23+E24-F24 -> 135
A25: 46163 | D25: Hydraulic Hose Pump | F25: 46 | G25: =G24+E25-F25 -> 89
G26: =G25+E26-F26 -> 89
G27: =G26+E27-F27 -> 89
G28: =G27+E28-F28 -> 89
G29: =G28+E29-F29 -> 89
G30: =G29+E30-F30 -> 89
G31: =G30+E31-F31 -> 89
G32: =G31+E32-F32 -> 89
G33: =G32+E33-F33 -> 89
G34: =G33+E34-F34 -> 89
G35: =G34+E35-F35 -> 89
G36: =G35+E36-F36 -> 89

Sheet HD-46 Hy Oil SERVO
A2: Edward & Christie(Pvt)Ltd
A3: Central Work Shop Badalgama
A4: Fuel & Lubricant Stock Book
A5: SERVO-46 Hy/Oil
A7: Date | B7: MR | C7: MTN | D7: Description | E7: Received | F7: Issued | G7: Balance | H7: Remark
A8: 45825 | B8: 7347 | D8: Main Stores | E8: 210 | G8: =E8 -> 210
A9: 45825 | B9: 112799 | C9: 2474 | D9: Batticoloa-LOT/02 | F9: 30 | G9: =G8+E9-F9 -> 180
A10: 45836 | B10: 113602 | C10: 2495 | D10: Batticoloa-LOT/03 | F10: 50 | G10: =G9+E10-F10 -> 130
A11: 45838 | D11: HEX-33-Kilinochchi | F11: 10 | G11: =G10+E11-F11 -> 120
A12: 45847 | D12: VR-71 | F12: 5 | G12: =G11+E12-F12 -> 115
A13: 45848 | D13: Batticoloa-LOT/02 | F13: 30 | G13: =G12+E13-F13 -> 85
A14: 45849 | D14: SL-02 | F14: 2 | G14: =G13+E14-F14 -> 83
A15: 45852 | D15: VR-23 | F15: 13.5 | G15: =G14+E15-F15 -> 69.5
A16: 45852 | D16: Service Truck | F16: 30 | G16: =G15+E16-F16 -> 39.5
A17: 45853 | D17: SL-03 | F17: 35 | G17: =G16+E17-F17 -> 4.5
A18: 45864 | D18: Returned From Service Truck | E18: 15 | G18: =G17+E18-F18 -> 19.5
A19: 45944 | D19: Batching Plant | F19: 1 | G19: =G18+E19-F19 -> 18.5
A20: 45971 | D20: Eecess Received | E20: 1.5 | G20: =G19+E20-F20 -> 20
A21: 45971 | B21: 206018 | C21: 64964 | D21: Ruwanwella Water Project | F21: 20 | G21: =G20+E21-F21 -> 0
G22: =G21+E22-F22 -> 0
G23: =G22+E23-F23 -> 0
G24: =G23+E24-F24 -> 0
G25: =G24+E25-F25 -> 0
G26: =G25+E26-F26 -> 0
G27: =G26+E27-F27 -> 0
G28: =G27+E28-F28 -> 0
G29: =G28+E29-F29 -> 0
G30: =G29+E30-F30 -> 0

Sheet Power Oil-1888
A1: Edward & Christie(Pvt)Ltd
A2: Central Work Shop Badalgama
A3: Fuel & Lubricant Stock Book
A4: Power Oil-1888
A6: Date | B6: MR | C6: MTN | D6: Description | E6: Received | F6: Issued | G6: Balance | H6: Remark
A7: 45812 | D7: B/F Balance | G7: 106
A8: 45813 | D8: 48-4849 | F8: 0.5 | G8: =G7+E8-F8 -> 105.5
A9: 45819 | D9: LD-8875 | F9: 0.75 | G9: =G8+E9-F9 -> 104.75
A10: 45820 | D10: LD-8875 | F10: 1 | G10: =G9+E10-F10 -> 103.75
A11: 45820 | D11: LI-3402 | F11: 0.5 | G11: =G10+E11-F11 -> 103.25
A12: 45824 | D12: From Service Truck | E12: 2 | G12: =G11+E12-F12 -> 105.25
A13: 45824 | D13: ZA-0447-Iginimitiya | F13: 2 | G13: =G12+E13-F13 -> 103.25
A14: 45825 | D14: 57-3062 | F14: 1 | G14: =G13+E14-F14 -> 102.25
A15: 45825 | D15: LD-05 | F15: 1 | G15: =G14+E15-F15 -> 101.25
A16: 45825 | D16: LP-1569 | F16: 0.25 | G16: =G15+E16-F16 -> 101
A17: 45827 | D17: ZA-0447-Iginimitiya | F17: 2 | G17: =G16+E17-F17 -> 99
A18: 45828 | D18: Service Truck | F18: 25 | G18: =G17+E18-F18 -> 74
A19: 45829 | B19: 177242 | C19: 2485 | D19: CEP-03 | F19: 4 | G19: =G18+E19-F19 -> 70
A20: 45832 | D20: Service Truck | F20: 50 | G20: =G19+E20-F20 -> 20
A21: 45835 | D21: LK-4057 | F21: 0.5 | G21: =G20+E21-F21 -> 19.5
A22: 45839 | B22: 177242 | C22: 31856 | D22: CEP-03 | F22: 4 | G22: =G21+E22-F22 -> 15.5
A23: 45841 | D23: LK-6740 | F23: 1 | G23: =G22+E23-F23 -> 14.5
A24: 45846 | D24: 325-5120 | F24: 1 | G24: =G23+E24-F24 -> 13.5
A25: 45847 | D25: Excess Received | E25: 1.5 | G25: =G24+E25-F25 -> 15
A26: 45847 | D26: Service Truck | F26: 15 | G26: =G25+E26-F26 -> 0
A27: 45862 | D27: Main Stores | E27: 210 | G27: =G26+E27-F27 -> 210
A28: 45862 | B28: 1947 | C28: 6404 | D28: CEP-03 | F28: 20 | G28: =G27+E28-F28 -> 190
A29: 45864 | D29: Service Truck | F29: 5 | G29: =G28+E29-F29 -> 185
A30: 45873 | D30: LK-2366 | F30: 0.5 | G30: =G29+E30-F30 -> 184.5
A31: 45883 | D31: Muthur Plant | F31: 10 | G31: =G30+E31-F31 -> 174.5
A32: 45888 | D32: DAH-4491 | F32: 0.5 | G32: =G31+E32-F32 -> 174
A33: 45888 | D33: Service Truck | F33: 15 | G33: =G32+E33-F33 -> 159
A34: 45893 | D34: DAH-2491 | F34: 0.5 | G34: =G33+E34-F34 -> 158.5
A35: 45896 | D35: Service Truck | F35: 15 | G35: =G34+E35-F35 -> 143.5
A36: 45898 | D36: 28-4314 | F36: 0.5 | G36: =G35+E36-F36 -> 143
A37: 45901 | D37: PH-6747 | F37: 1 | G37: =G36+E37-F37 -> 142
A38: 45906 | D38: DAH-2491 | F38: 0.25 | G38: =G37+E38-F38 -> 141.75
A39: 45917 | D39: GL-0019 | F39: 1 | G39: =G38+E39-F39 -> 140.75
A40: 45927 | B40: 142529 | C40: 72111 | D40: Marawila | F40: 5 | G40: =G39+E40-F40 -> 135.75
A41: 45935 | D41: PH-6744 | F41: 1 | G41: =G40+E41-F41 -> 134.75
...

Sheet MP-90 Gear Oil
A1: Edward & Christie(Pvt)Ltd
A2: Central Work Shop Badalgama
A3: Fuel & Lubricant Stock Book
A4: MP-90 Gear Oil
A6: Date | B6: MR | C6: MTN | D6: Description | E6: Received | F6: Issued | G6: Balance | H6: Remark
A7: 45809 | D7: B/F Balance | G7: 91
A8: 45811 | D8: Main Stores | E8: 210 | G8: =G7+E8-F8 -> 301
A9: 45811 | D9: CEP-03 | F9: 100 | G9: =G8+E9-F9 -> 201
A10: 45819 | D10: LD-8875 | F10: 5 | G10: =G9+E10-F10 -> 196
A11: 45820 | D11: LI-3402 | F11: 3 | G11: =G10+E11-F11 -> 193
A12: 45822 | D12: LM-6653 | F12: 1 | G12: =G11+E12-F12 -> 192
A13: 45823 | D13: SR-04 | F13: 1 | G13: =G12+E13-F13 -> 191
A14: 45825 | D14: Batticoloa-LOT-02 | F14: 30 | G14: =G13+E14-F14 -> 161
A15: 45826 | D15: ZA-6255 | F15: 5 | G15: =G14+E15-F15 -> 156
A16: 45826 | D16: ZA-6255 | F16: 2 | G16: =G15+E16-F16 -> 154
A17: 45826 | D17: ZA-6255 | F17: 1 | G17: =G16+E17-F17 -> 153
A18: 45828 | D18: Service Truck | F18: 20 | G18: =G17+E18-F18 -> 133
A19: 45828 | D19: LC-0434 | F19: 1 | G19: =G18+E19-F19 -> 132
A20: 45832 | D20: Service Truck | F20: 50 | G20: =G19+E20-F20 -> 82
... A23: 45847 | D23: VR-71 | F23: 15 | G23: =G22+E23-F23 -> 51
A24: 45848 | D24: Excess Received | E24: 13 | G24: =G23+E24-F24 -> 64
A25: 45848 | D25: Muthur Plant | F25: 60 | G25: =G24+E25-F25 -> 4
A26: 45848 | D26: Service Truck | F26: 4 | G26: =G25+E26-F26 -> 0
A27: 45852 | D27: Main Stores | E27: 210 | G27: =G26+E27-F27 -> 210
A28: 45852 | B28: 1936 | C28: 31882 | D28: CEP-03 | F28: 20 | G28: =G27+E28-F28 -> 190
A29: 45851 | D29: HEX-29 | F29: 4 | G29: =G28+E29-F29 -> 186
A30: 45856 | D30: LK-2366 | F30: 8 | G30: =G29+E30-F30 -> 178
A31: 45859 | D31: LO-9810 | F31: 8 | G31: =G30+E31-F31 -> 170
A32: 45860 | D32: LL-1782 | F32: 2 | G32: =G31+E32-F32 -> 168
A33: 45861 | D33: HEX-21 | F33: 1.5 | G33: =G32+E33-F33 -> 166.5
A34: 45862 | D34: CEP-03 | F34: 50 | G34: =G33+E34-F34 -> 116.5
A35: 45869 | D35: RA-3052 | F35: 27 | G35: =G34+E35-F35 -> 89.5
A36: 45870 | B36: 173822 | C36: 6416 | D36: NBRO-Kalalgamuwa | F36: 4 | G36: =G35+E36-F36 -> 85.5
A37: 45872 | D37: HEX-45 | F37: 8 | G37: =G36+E37-F37 -> 77.5
A38: 45881 | D38: HEX-23 | F38: 10 | G38: =G37+E38-F38 -> 67.5
A39: 45883 | D39: RD-3536 | F39: 20 | G39: =G38+E39-F39 -> 47.5
A40: 45883 | D40: Main Stores | E40: 210 | G40: =G39+E40-F40 -> 257.5
A41: 45885 | D41: RD-3536 | F41: 3 | G41: =G40+E41-F41 -> 254.5
A42: 45885 | D42: RD-3536 | F42: 3 | G42: =G41+E42-F42 -> 251.5
A43: 45887 | D43: ZA-9716 | F43: 10 | G43: =G42+E43-F43 -> 241.5
...

Sheet 80W90 (Caltex)
A1: Edward & Christie(Pvt)Ltd
A2: Central Work Shop Badalgama
A3: Fuel & Lubricant Stock Book
A4: 80W90 Gear Oil
A6: Date | B6: MR | C6: MTN | D6: Description | E6: Received | F6: Issued | G6: Balance | H6: Remark
A7: 45809 | D7: B/F Balance | G7: 204.5
A8: 45810 | D8: Service Team | F8: 204.5 | G8: =G7+E8-F8 -> 0
A9: 45816 | D9: Returned From Service Team | E9: 10 | G9: =G8+E9-F9 -> 10
A10: 45816 | D10: LO-7183 | F10: 10 | G10: =G9+E10-F10 -> 0
A11: 45817 | D11: Returned From Service Team | E11: 10 | G11: =G10+E11-F11 -> 10
A12: 45817 | D12: LK-5041 | F12: 10 | G12: =G11+E12-F12 -> 0
A13: 45820 | D13: Returned From Service Team | E13: 2 | G13: =G12+E13-F13 -> 2
A14: 45820 | D14: LI-3402 | F14: 2 | G14: =G13+E14-F14 -> 0
A15: 45838 | B15: 7328 | D15: Main Stores | E15: 210 | G15: =G14+E15-F15 -> 210
A16: 45839 | D16: LP-1574 | F16: 10 | G16: =G15+E16-F16 -> 200
A17: 45839 | D17: LJ-5203 | F17: 9 | G17: =G16+E17-F17 -> 191
A18: 45841 | D18: HS-1794 | F18: 2 | G18: =G17+E18-F18 -> 189
A19: 45842 | D19: LP-1571 | F19: 9 | G19: =G18+E19-F19 -> 180
A20: 45845 | D20: LD-05 | F20: 24 | G20: =G19+E20-F20 -> 156
A21: 45846 | D21: LD-05 | F21: 4 | G21: =G20+E21-F21 -> 152
A22: 45881 | D22: PJ-6376 | F22: 4 | G22: =G21+E22-F22 -> 148
A23: 45851 | D23: LK-4057 | F23: 8 | G23: =G22+E23-F23 -> 140
A24: 45854 | D24: MG-18 | F24: 45 | G24: =G23+E24-F24 -> 95
A25: 45863 | D25: LD-06 | F25: 15 | G25: =G24+E25-F25 -> 80
A26: 45864 | D26: Service Team | F26: 20 | G26: =G25+E26-F26 -> 60
A27: 45868 | D27: LP-1572 | F27: 9 | G27: =G26+E27-F27 -> 51
... A32: 45893 | D32: ZB-2587 | F32: 17 | G32: =G31+E32-F32 -> 0.5
A33: 45896 | B33: 174541 | D33: Main Stores | E33: 210 | G33: =G32+E33-F33 -> 210.5
A34: 45896 | D34: Service Team | F34: 30 | G34: =G33+E34-F34 -> 180.5
A35: 45908 | D35: LP-1578 | F35: 8 | G35: =G34+E35-F35 -> 172.5
A36: 45908 | D36: LI-7620 | F36: 1 | G36: =G35+E36-F36 -> 171.5
A37: 45909 | D37: HU-5097 | F37: 0.5 | G37: =G36+E37-F37 -> 171
A38: 45918 | D38: LK-5047 | F38: 6 | G38: =G37+E38-F38 -> 165
A39: 45925 | D39: LO-4822 | F39: 1 | G39: =G38+E39-F39 -> 164
A40: 45931 | D40: DAH-2230 | F40: 3 | G40: =G39+E40-F40 -> 161
A41: 45941 | B41: 2111 | C41: 72137 | D41: CEP-03 | F41: 50 | G41: =G40+E41-F41 -> 111
A42: 45941 | D42: PD-6917 | F42: 4 | G42: =G41+E42-F42 -> 107
A43: 45944 | D43: Batching Plant | F43: 2 | G43: =G42+E43-F43 -> 105
A44: 45945 | D44: LO-4824 | F44: 9 | G44: =G43+E44-F44 -> 96
A45: 45962 | D45: LK-6738 | F45: 1 | G45: =G44+E45-F45 -> 95
...

Sheet 80W90 G-Oil (Servo)
A1: Edward & Christie(Pvt)Ltd
A2: Central Work Shop Badalgama
A3: Fuel & Lubricant Stock Book
A4: 80W90 Gear Oil (Servo)
A6: Date | B6: MR | C6: MTN | D6: Description | E6: Received | F6: Issued | G6: Balance | H6: Remark
A7: 45961 | E7: 210 | G7: =E7 -> 210
A8: 45962 | D8: LK-6738 | F8: 1 | G8: =G7+E8-F8 -> 209
A9: 46366 | D9: ZA-8337 | F9: 15 | G9: =G8+E9-F9 -> 194
A10: 46007 | D10: Lathe Machine | F10: 15 | G10: =G9+E10-F10 -> 179
A11: 46017 | D11: LD-05 | F11: 26 | G11: =G10+E11-F11 -> 153
A12: 46018 | D12: LI-7620 | F12: 9 | G12: =G11+E12-F12 -> 144
A13: 46020 | D13: LK-4061 | F13: 8 | G13: =G12+E13-F13 -> 136
A14: 46020 | D14: HS-1794 | F14: 7 | G14: =G13+E14-F14 -> 129
A15: 6 | D15: 325-3448 | F15: 5 | G15: =G14+E15-F15 -> 124
A16: 46033 | D16: PA-4879 | F16: 3.5 | G16: =G15+E16-F16 -> 120.5
A17: 46035 | D17: LK-5048 | F17: 5 | G17: =G16+E17-F17 -> 115.5
A18: 46036 | D18: LB-01 | F18: 20 | G18: =G17+E18-F18 -> 95.5
A19: 46051 | D19: Lathe Machine | F19: 3 | G19: =G18+E19-F19 -> 92.5
... A22: 46177 | D22: LI-3851 | F22: 10 | G22: =G21+E22-F22 -> 63.5
G23: =G22+E23-F23 -> 63.5
G24: =G23+E24-F24 -> 63.5
G25: =G24+E25-F25 -> 63.5
G26: =G25+E26-F26 -> 63.5
G27: =G26+E27-F27 -> 63.5
G28: =G27+E28-F28 -> 63.5
G29: =G28+E29-F29 -> 63.5
G30: =G29+E30-F30 -> 63.5
G31: =G30+E31-F31 -> 63.5
G32: =G31+E32-F32 -> 63.5
G33: =G32+E33-F33 -> 63.5
G34: =G33+E34-F34 -> 63.5
... G62: =G61+E62-F62 -> 63.5

Sheet MP-140 G-Oil
A1: Edward & Christie(Pvt)Ltd
A2: Central Work Shop Badalgama
A3: Fuel & Lubricant Stock Book
A4: MP-140 Gear Oil
A6: Date | B6: MR | C6: MTN | D6: Description | E6: Received | F6: Issued | G6: Balance | H6: Remark
G7: 124
A8: 45810 | D8: Service Team | F8: 124 | G8: =G7+E8-F8 -> 0
A9: 45812 | D9: Returned From Service Team | E9: 65 | G9: =G8+E9-F9 -> 65
A10: 45816 | D10: LO-7183 | F10: 15 | G10: =G9+E10-F10 -> 50
A11: 45817 | D11: LK-5041 | F11: 30 | G11: =G10+E11-F11 -> 20
A12: 45825 | D12: LP-1569 | F12: 15 | G12: =G11+E12-F12 -> 5
A13: 45833 | D13: Main Stores | E13: 210 | G13: =G12+E13-F13 -> 215
A14: 45833 | D14: Service Team | F14: 60 | G14: =G13+E14-F14 -> 155
A15: 45842 | D15: LP-1574 | F15: 17 | G15: =G14+E15-F15 -> 138
A16: 45871 | D16: LP-1568 | F16: 14 | G16: =G15+E16-F16 -> 124
A17: 45885 | D17: LY-1614 | F17: 16 | G17: =G16+E17-F17 -> 108
A18: 45887 | D18: HO-9850 | F18: 14.5 | G18: =G17+E18-F18 -> 93.5
A19: 45908 | D19: LP-1578 | F19: 14 | G19: =G18+E19-F19 -> 79.5
A20: 45928 | D20: LN-8278 | F20: 7 | G20: =G19+E20-F20 -> 72.5
A21: 45929 | D21: 48-4849 | F21: 1 | G21: =G20+E21-F21 -> 71.5
A22: 45929 | D22: LP-1577 | F22: 13 | G22: =G21+E22-F22 -> 58.5
A23: 45937 | D23: Service Team | F23: 20 | G23: =G22+E23-F23 -> 38.5
A24: 45946 | D24: LO-4824 | F24: 14 | G24: =G23+E24-F24 -> 24.5
A25: 45974 | D25: Main Stores | E25: 210 | G25: =G24+E25-F25 -> 234.5
A26: 45974 | D26: LO-5984 | F26: 14 | G26: =G25+E26-F26 -> 220.5
A27: 45976 | D27: LM-5720 | F27: 17 | G27: =G26+E27-F27 -> 203.5
A28: 45998 | D28: LO-0434 | F28: 10 | G28: =G27+E28-F28 -> 193.5
A29: 46000 | D29: LK-5041 | F29: 15 | G29: =G28+E29-F29 -> 178.5
A30: 46001 | D30: 48-4849 | F30: 10 | G30: =G29+E30-F30 -> 168.5
A31: 46008 | D31: LO-5984 | F31: 2 | G31: =G30+E31-F31 -> 166.5
A32: 46008 | D32: ZA-7925 | F32: 17 | G32: =G31+E32-F32 -> 149.5
A33: 46009 | D33: LI-3851 | F33: 13 | G33: =G32+E33-F33 -> 136.5
A34: 46012 | D34: LO-4822 | F34: 14 | G34: =G33+E34-F34 -> 122.5
A35: 46013 | D35: LK-4057 | F35: 15 | G35: =G34+E35-F35 -> 107.5
A36: 46013 | D36: LE-4986 | F36: 12 | G36: =G35+E36-F36 -> 95.5
A37: 46014 | D37: LJ-8055 | F37: 7 | G37: =G36+E37-F37 -> 88.5
... A40: 46018 | D40: LI-7620 | F40: 14 | G40: =G39+E40-F40 -> 26.5
A41: 46024 | D41: Main Stores | E41: 210 | G41: =G40+E41-F41 -> 236.5
A42: 46024 | D42: LK-4061 | F42: 34 | G42: =G41+E42-F42 -> 202.5
A43: 46036 | D43: LK-5048 | F43: 5 | G43: =G42+E43-F43 -> 197.5
...

Sheet Grease
A1: Edward & Christie(Pvt)Ltd
A2: Central Work Shop Badalgama
A3: Fuel & Lubricant Stock Book
A4: GREASE
A6: Date | B6: MR | C6: MTN | D6: Description | E6: Received | F6: Issued | G6: Balance | H6: Remark
A7: 45809 | D7: B/F Balance | G7: 0
A8: 45811 | B8: 5141 | D8: Main Stores | E8: 182 | G8: =G7+E8-F8 -> 182
A9: 45811 | B9: 1837 | C9: 2456 | D9: CEP-03 | F9: 100 | G9: =G8+E9-F9 -> 82
A10: 45812 | B10: 179993 | C10: 2457 | D10: Batticoloa | F10: 50 | G10: =G9+E10-F10 -> 32
A11: 45815 | D11: Service Team | F11: 10 | G11: =G10+E11-F11 -> 22
A12: 45820 | D12: LM-6653 | F12: 1 | G12: =G11+E12-F12 -> 21
A13: 45821 | B13: 23932 | C13: 2468 | D13: Ruwanwella W/Project | F13: 20 | G13: =G12+E13-F13 -> 1
A14: 45822 | D14: Main Stores | E14: 182 | G14: =G13+E14-F14 -> 183
A15: 45825 | B15: 21019 | C15: 2471 | D15: Iginimitiya | F15: 5 | G15: =G14+E15-F15 -> 178
A16: 45825 | D16: Batticoloa-LOT-02 | F16: 100 | G16: =G15+E16-F16 -> 78
A17: 45825 | D17: Service Team | F17: 10 | G17: =G16+E17-F17 -> 68
A18: 45836 | B18: 113602 | C18: 2495 | D18: Batticoloa-LOT-03 | F18: 10 | G18: =G17+E18-F18 -> 58
A19: 45838 | D19: Asphalt Plant | F19: 2 | G19: =G18+E19-F19 -> 56
A20: 45839 | D20: CEP-03 | F20: 10 | G20: =G19+E20-F20 -> 46
A21: 45840 | B21: 23117 | C21: 31859 | D21: Ruwanwella W/Project | F21: 15 | G21: =G20+E21-F21 -> 31
A22: 45840 | B22: 7331 | D22: Main Stores | E22: 182 | G22: =G21+E22-F22 -> 213
A23: 45841 | B23: 23177 | C23: 31861 | D23: Ruwanwella W/Project | F23: 15 | G23: =G22+E23-F23 -> 198
A24: 45842 | B24: 1864 | C24: 31864 | D24: CEP-03-E | F24: 100 | G24: =G23+E24-F24 -> 98
A25: 45843 | D25: Asphalt Plant | F25: 5 | G25: =G24+E25-F25 -> 93
A26: 45843 | D26: Service Team | F26: 10 | G26: =G25+E26-F26 -> 83
A27: 45843 | D27: LP-1571 | F27: 3 | G27: =G26+E27-F27 -> 80
A28: 45844 | D28: Service Bay | F28: 15 | G28: =G27+E28-F28 -> 65
A29: 45846 | D29: CEP-03 | F29: 20 | G29: =G28+E29-F29 -> 45
A30: 45848 | D30: Kilinochchi. | F30: 10 | G30: =G29+E30-F30 -> 35
A31: 45854 | D31: NBRO-Kalalgamuwa | F31: 15 | G31: =G30+E31-F31 -> 20
A32: 45859 | D32: Marawila Rd/Project | F32: 5 | G32: =G31+E32-F32 -> 15
A33: 45860 | D33: Main Stores | E33: 182 | G33: =G32+E33-F33 -> 197
A34: 45861 | D34: LO-7855 | F34: 3 | G34: =G33+E34-F34 -> 194
A35: 45862 | D35: CEP-03 | F35: 50 | G35: =G34+E35-F35 -> 144
A36: 45865 | B36: 113637 | C36: 31900 | D36: Batticoloa-LOT-03 | F36: 50 | G36: =G35+E36-F36 -> 94
A37: 45866 | D37: Service Bay | F37: 15 | G37: =G36+E37-F37 -> 79
A38: 45873 | D38: HEX-45 | F38: 5.5 | G38: =G37+E38-F38 -> 73.5
A39: 45875 | B39: 174518 | D39: Main Stores | E39: 182 | G39: =G38+E39-F39 -> 255.5
A40: 45875 | B40: 4797 | C40: 6430 | D40: Kilinochchi. | F40: 22 | G40: =G39+E40-F40 -> 233.5
A41: 45875 | B41: 1979 | C41: 6429 | D41: CEP-03 | F41: 60 | G41: =G40+E41-F41 -> 173.5
...

Sheet K-Oil
A1: Edward & Christie(Pvt)Ltd
A2: Central Work Shop Badalgama
A3: Fuel & Lubricant Stock Book
A4: 15W40 (CI-04)Engine Oil
A6: Date | B6: MR | C6: MTN | D6: Description | E6: Received | F6: Issued | G6: Balance | H6: Remark
A7: 45916 | B7: 6494 | G7: 21.6
A8: 45917 | D8: New Where House Building | F8: 1 | G8: =G7+E8-F8 -> 20.6
A9: 45917 | D9: ZA-8033 | F9: 2 | G9: =G8+E9-F9 -> 18.6
A10: 45918 | D10: HEX-45 | F10: 2.5 | G10: =G9+E10-F10 -> 16.1
A11: 45918 | D11: LK-5047 | F11: 3 | G11: =G10+E11-F11 -> 13.1
A12: 45919 | D12: LK-6740 | F12: 3 | G12: =G11+E12-F12 -> 10.1
A13: 45922 | D13: Asphalt Plant | F13: 2 | G13: =G12+E13-F13 -> 8.1
A14: 45923 | D14: LM-5720 | F14: 1 | G14: =G13+E14-F14 -> 7.1
A15: 45923 | D15: YARD | F15: 1.5 | G15: =G14+E15-F15 -> 5.6
A16: 45923 | D16: PTR-01 | F16: 2 | G16: =G15+E16-F16 -> 3.6
A17: 45924 | D17: MGS-01 | F17: 1 | G17: =G16+E17-F17 -> 2.6
A18: 45924 | D18: LP-1578 | F18: 1 | G18: =G17+E18-F18 -> 1.6
A19: 45924 | D19: YARD | F19: 1.6 | G19: =G18+E19-F19 -> 0
A20: 45926 | E20: 10 | G20: =G19+E20-F20 -> 10
A21: 45926 | D21: LM-6653 | F21: 1 | G21: =G20+E21-F21 -> 9
A22: 45926 | D22: PTR-01 | F22: 1 | G22: =G21+E22-F22 -> 8
A23: 45926 | D23: LM-6653 | F23: 2 | G23: =G22+E23-F23 -> 6
A24: 45926 | D24: CR-02 | F24: 0.5 | G24: =G23+E24-F24 -> 5.5
A25: 45926 | D25: LM-6653 | F25: 1 | G25: =G24+E25-F25 -> 4.5
A26: 45927 | D26: LM-6653 | F26: 2 | G26: =G25+E26-F26 -> 2.5
A27: 45927 | D27: LN-8279 | F27: 2 | G27: =G26+E27-F27 -> 0.5
A28: 45927 | D28: PTR-01 | F28: 0.5 | G28: =G27+E28-F28 -> 0
A29: 45927 | D29: L/P | E29: 10 | G29: =G28+E29-F29 -> 10
A30: 45928 | D30: Servce Bay | F30: 1 | G30: =G29+E30-F30 -> 9
A31: 45929 | D31: 48-4849 | F31: 1 | G31: =G30+E31-F31 -> 8
A32: 45932 | D32: ZA-8033 | F32: 2 | G32: =G31+E32-F32 -> 6
A33: 45933 | D33: PA-6399 | F33: 2 | G33: =G32+E33-F33 -> 4
A34: 45934 | D34: Alternater Cleanig | F34: 1 | G34: =G33+E34-F34 -> 3
A35: 45934 | D35: HEX-17 | F35: 2 | G35: =G34+E35-F35 -> 1
A36: 45935 | D36: GE-04 | F36: 1 | G36: =G35+E36-F36 -> 0
A37: 45935 | D37: L/P | E37: 20.6 | G37: =G36+E37-F37 -> 20.6
A38: 45937 | D38: PD-6917 | F38: 2 | G38: =G37+E38-F38 -> 18.6
A39: 45940 | D39: LL-1782 | F39: 2 | G39: =G38+E39-F39 -> 16.6
A40: 45940 | D40: LL-1782 | F40: 2 | G40: =G39+E40-F40 -> 14.6
A41: 45940 | D41: LK-5041 | F41: 1.6 | G41: =G40+E41-F41 -> 13
...

Sheet PETROL
A1: Edward & Christie(Pvt)Ltd
A2: Central Work Shop Badalgama
A3: Fuel & Lubricant Stock Book
A4: 15W40 (CI-04)Engine Oil
A6: Date | B6: MR | C6: MTN | D6: Description | E6: Received | F6: Issued | G6: Balance | H6: Remark
A7: 46140 | D7: Balance | G7: 1
A8: 46144 | D8: LY-4524 | F8: 0.5 | G8: =G7+E8-F8 -> 0.5
A9: 46146 | D9: Fire Training | F9: 0.5 | G9: =G8+E9-F9 -> 0
A10: 46146 | D10: LP | E10: 3.65 | G10: =G9+E10-F10 -> 3.65
A11: 46151 | D11: 51-7158 | F11: 0.5 | G11: =G10+E11-F11 -> 3.15
A12: 46153 | D12: LD-08 | F12: 0.5 | G12: =G11+E12-F12 -> 2.65
A13: 46168 | D13: SR-12 | F13: 0.5 | G13: =G12+E13-F13 -> 2.15
A14: 46170 | D14: LK-4058 | F14: 0.5 | G14: =G13+E14-F14 -> 1.65
A15: 46175 | D15: 57-3062 | F15: 0.5 | G15: =G14+E15-F15 -> 1.15
G16: =G15+E16-F16 -> 1.15
G17: =G16+E17-F17 -> 1.15
G18: =G17+E18-F18 -> 1.15
G19: =G18+E19-F19 -> 1.15
G20: =G19+E20-F20 -> 1.15
G21: =G20+E21-F21 -> 1.15
G22: =G21+E22-F22 -> 1.15
G23: =G22+E23-F23 -> 1.15
G24: =G23+E24-F24 -> 1.15
G25: =G24+E25-F25 -> 1.15
G26: =G25+E26-F26 -> 1.15
G27: =G26+E27-F27 -> 1.15
... G39: =G38+E39-F39 -> 1.15

Sheet HUB GREASE
A1: Edward & Christie(Pvt)Ltd
A2: Central Work Shop Badalgama
A3: Fuel & Lubricant Stock Book
A4: HUB GREASE
A6: Date | B6: MR | C6: MTN | D6: Description | E6: Received | F6: Issued | G6: Balance | H6: Remark
A7: 46106 | B7: 142331 | D7: Main Stores Badalgama | E7: 18 | G7: =E7 -> 18
A8: 46116 | D8: Batticloa Work Shop | F8: 5 | G8: =G7+E8-F8 -> 13
A9: 46147 | D9: ZA-2609 / LB01 | F9: 1 | G9: =G8+E9-F9 -> 12
A10: 46150 | D10: LC-0434 | F10: 2 | G10: =G9+E10-F10 -> 10
A11: 46154 | D11: LX-1679 | F11: 1.5 | G11: =G10+E11-F11 -> 8.5
A12: 46154 | D12: LX-1679 | F12: 3.5 | G12: =G11+E12-F12 -> 5
A13: 46176 | D13: PH-6744 | F13: 0.5 | G13: =G12+E13-F13 -> 4.5
G14: =G13+E14-F14 -> 4.5
G15: =G14+E15-F15 -> 4.5
G16: =G15+E16-F16 -> 4.5
G17: =G16+E17-F17 -> 4.5
G18: =G17+E18-F18 -> 4.5
G19: =G18+E19-F19 -> 4.5
G20: =G19+E20-F20 -> 4.5

Sheet cotten waste
A1: Edward & Christie(Pvt)Ltd
A2: Central Work Shop Badalgama
A3: Fuel & Lubricant Stock Book
A4: cotton waste
A6: Date | B6: MR | C6: MTN | D6: Description | E6: Received | F6: Issued | G6: Balance | H6: Remark
A7: 46144 | D7: B/F | G7: 1
A8: 46145 | D8: Work Shop | F8: 0.5 | G8: =G7+E8-F8 -> 0.5
A9: 46146 | D9: Work Shop | F9: 0.5 | G9: =G8+E9-F9 -> 0
A10: 46147 | B10: 142337 | D10: LP | E10: 10 | G10: =G9+E10-F10 -> 10
A11: 46147 | D11: Work Shop | F11: 1.5 | G11: =G10+E11-F11 -> 8.5
A12: 46148 | D12: Work Shop | F12: 1.25 | G12: =G11+E12-F12 -> 7.25
A13: 46149 | D13: Work Shop | F13: 1.75 | G13: =G12+E13-F13 -> 5.5
A14: 46150 | D14: Work Shop | F14: 2 | G14: =G13+E14-F14 -> 3.5
A15: 46151 | D15: Work Shop | F15: 1 | G15: =G14+E15-F15 -> 2.5
A16: 46152 | D16: Work Shop | F16: 0.75 | G16: =G15+E16-F16 -> 1.75
A17: 46153 | D17: Work Shop | F17: 0.75 | G17: =G16+E17-F17 -> 1
A18: 46154 | D18: Work Shop | F18: 1 | G18: =G17+E18-F18 -> 0
A19: 46155 | B19: 142337 | D19: LP | E19: 7.6 | G19: =G18+E19-F19 -> 7.6
A20: 46155 | D20: Work Shop | F20: 2.5 | G20: =G19+E20-F20 -> 5.1
A21: 46156 | D21: Work Shop | F21: 1 | G21: =G20+E21-F21 -> 4.1
A22: 46157 | D22: Work Shop | F22: 1 | G22: =G21+E22-F22 -> 3.1
A23: 46158 | D23: Work Shop | F23: 1.5 | G23: =G22+E23-F23 -> 1.6
A24: 46159 | D24: Work Shop | F24: 0.6 | G24: =G23+E24-F24 -> 1
A25: 46160 | D25: Work Shop | F25: 1 | G25: =G24+E25-F25 -> 0
G26: =G25+E26-F26 -> 0
G27: =G26+E27-F27 -> 0
G28: =G27+E28-F28 -> 0
G29: =G28+E29-F29 -> 0
G30: =G29+E30-F30 -> 0
G31: =G30+E31-F31 -> 0
G32: =G31+E32-F32 -> 0
G33: =G32+E33-F33 -> 0
G34: =G33+E34-F34 -> 0
G35: =G34+E35-F35 -> 0
G36: =G35+E36-F36 -> 0
G37: =G36+E37-F37 -> 0

Sheet Sheet1
A1: Edward & Christie(Pvt)Ltd
A2: Central Work Shop Badalgama | E2: PORT CITY
A3: Fuel & Lubricant Issues
A4: Date | B4: MR | C4: MTN | D4: Item | E4: Re/Qty | F4: Issued | G4: Balance | H4: Remark

Sheet Sheet2
B6: OIL MR
C15: 1906.78 | E15: 5508.47
C16: 2118.64 | E16: 12711.86
C17: 3050.85 | E17: 12711.86
C18: 1906.78 | E18: 1271.19
C19: 5932.2 | E19: 4237.29
C20: =SUM(C15:C19) -> 14915.25 | E20: =SUM(E15:E19) -> 36440.67
C21: 8050.85 | E21: =E20*0.18 -> 6559.3206
C22: 10593.22 | E22: =SUM(E20:E21) -> 42999.991
C23: 4067.8
C24: 5720.34
C25: =SUM(C20:C24) -> 43347.46
C26: =C25*0.18 -> 7802.5428
C27: =SUM(C25:C26) -> 51150.003

Sheet Sheet3
B1: Material Note | F1: Material Note
A2: Date : | E2: Date :
A3: Vehicle No : | E3: Vehicle No :
A13: Name | E13: Name
A14: Designation | E14: Designation
A15: Signature | E15: Signature
B17: Material Note | F17: Material Note
A18: Date : | E18: Date :
A19: Vehicle No : | E19: Vehicle No :
A29: Name | E29: Name
A30: Designation | E30: Designation
A31: Signature | E31: Signature
B33: Material Note | F33: Material Note
A34: Date : | E34: Date :
A35: Vehicle No : | E35: Vehicle No :
A45: Name | E45: Name
A46: Designation | E46: Designation
A47: Signature | E47: Signature
